Workbook

Sheet Modelo de Dominio
A1: Ir a objeto de dominio>>>
A3: #VALUE!

Sheet Objetos de Dominio
A1: <<<Ir al modelo de dominio
A2: Nombre | B2: Descripción | C2: Linea de vida | D2: Muestreo de Datos | E2: Caracterización objeto | F2: EventStorming | G2: Politicas
A3: Pais | B3: Representa el país al que pertenecen las sedes. | C3: 1 | D3: Ver | E3: Ver | F3: Ver | G3: Ver
A4: MetodoPago | B4: Representa las formas en que un cliente puede cancelar una compra (efectivo, tarjeta, transferencia, Nequi, entre otras). | C4: 1 | D4: Ver | E4: Ver | F4: Ver | G4: Ver
A5: Cliente | B5: Representa a la persona que adquiere productos en cualquiera de las sedes del negocio. | C5: 1 | D5: Ver | E5: Ver | F5: Ver | G5: Ver
A6: Marca | B6: Representa al fabricante de los accesorios y repuestos que comercializa el negocio. | C6: 1 | D6: Ver | E6: Ver | F6: Ver | G6: Ver
A7: Motivo | B7: Representa la razón por la que un cliente solicita devolver un producto. | C7: 1 | D7: Ver | E7: Ver | F7: Ver | G7: Ver
A8: TipoDocumento | B8: Representa el tipo de documento de identidad de una persona | C8: 1 | D8: Ver | E8: Ver | F8: Ver | G8: Ver
A9: Categoria | B9: Representa la clasificación a la que pertenece un producto dentro del catálogo. | C9: 1 | D9: Ver | E9: Ver | F9: Ver | G9: Ver
A10: Prefijo | B10: Representa el código de marcado telefónico asociado a un país para el registro de números de contacto | C10: 1 | D10: Ver | E10: Ver | F10: Ver | G10: Ver
A11: Persona | B11: Representa a un individuo en el sistema con sus datos generales de identificación para registrarse en el sistema | C11: 2 | D11: Ver | E11: Ver | F11: Ver | G11: Ver
A12: Producto | B12: Representa un artículo del catálogo general del negocio, independiente de la sede en la que se encuentre. | C12: 2 | D12: Ver | E12: Ver | F12: Ver | G12: Ver
A13: Departamento | B13: Representa el departamento o división administrativa al que pertenece una ciudad dentro de un país. | C13: 2 | D13: Ver | E13: Ver | F13: Ver | G13: Ver
A14: ClienteRegistrado | B14: Representa al cliente cuyos datos de identificación y contacto han sido registrados en el sistema | C14: 2 | D14: Ver | E14: Ver | F14: Ver | G14: Ver
... A34: AplicacionSaldo | B34: Representa el uso de un saldo a favor sobre un pago con saldo, y permite controlar el saldo de un cliente específico. | C34: 10 | D34: Ver | E34: Ver | F34: Ver | G34: Ver

Sheet M-Pais
A1: <<<Ir al modelo de dominio | B1: <<<Ir a objeto de dominio | C1: Ir a la caracterización>>> | D1: Ir al event storming>>> | E1: Ir a las políticas>>>
A2: Nombre: | B2: ='Objetos de Dominio'!A3 -> Pais
A3: Descripción: | B3: ='Objetos de Dominio'!B3 -> Representa el país al que pertenecen las sedes.
A4: Identificador único del país | B4: Nombre oficial del país | C4: Combinación única que indica que no puede existir más de un país con el mismo nombre
A5: ID | B5: Nombre | C5: PaisUnico
A6: 1 | B6: Colombia | C6: =B6 -> Colombia
A7: 2 | B7: Ecuador | C7: =B7 -> Ecuador
A8: 3 | B8: Perú | C8: =B8 -> Perú

Sheet C-Pais
A1: <<<Ir al modelo de dominio | B1: <<<Ir a objeto de dominio | C1: <<<Ir a muestreo del objeto | D1: Ir al event storming>>> | E1: Ir a las políticas>>>
A2: Nombre | B2: ='Objetos de Dominio'!A3 -> Pais
A3: Descripción | B3: ='Objetos de Dominio'!B3 -> Representa el país al que pertenecen las sedes.
A4: Nombre atributo | B4: Descripción atributo | C4: Identificador del objeto de dominio | D4: Tipo de dato | E4: Obligatorio | F4: Longitud mínima (si aplica) | G4: Longitud máxima (si aplica) | H4: Precisión (si aplica) | I4: Redondeo (si aplica) | J4: Rango inicial (si aplica) | K4: Rango final (si aplica) | L4: Formato (si aplica) | M4: Reglas especiales (si aplica) | N4: Dato calculado | O4: Aplica ajuste del dato (si aplica) | P4: Carácter de ajuste (si aplica) | Q4: Quitar espacios en blanco al inicio (si aplica) | R4: Quitar espacios en blanco al fin (si aplica) | S4: Dato sensible (si aplica) | T4: Valor por defecto (si aplica) | U4: Auto generado | V4: =HYPERLINK("#'C-Pais'!A16","buscarPaisPorFiltro") -> buscarPaisPorFiltro
A5: ID | B5: ='M-Pais'!A4 -> Identificador único del país | C5: Si | D5: Identificador único universal | E5: Si | F5: - | G5: - | H5: - | I5: - | J5: - | K5: - | L5: - | M5: Debe ser único y no debe repetirse en los distintos id's de los países | N5: No | O5: No | P5: - | Q5: No | R5: No | S5: - | T5: - | U5: Si | V5: Filtro | W5: No Mostrar
A6: Nombre | B6: ='M-Pais'!B4 -> Nombre oficial del país | C6: No | D6: Texto | E6: Si | F6: 2 | G6: 100 | H6: - | I6: - | J6: - | K6: - | L6: - | M6: Se debe asegurar una sanitización del dato, para garantizar que dentro de su contenido no tenga cualquier tipo de intento de ataque | N6: No | O6: No | P6: - | Q6: Si | R6: Si | S6: - | T6: - | U6: No | V6: Filtro | W6: Mostrar
A9: Nombre combinación única | B9: Descripción | C9: Atributos involucrados
A10: ='M-Pais'!C5 -> PaisUnico | B10: ='M-Pais'!C4 -> Combinación única que indica que no puede existir más de un país con el mismo nombre | C10: Nombre
A14: Responsabilidad | C14: Descripción | G14: Entradas | J14: Salida | O14: Políticas (Reglas de Negocio) | Q14: Excepción
G15: Parámetro | H15: Tipo de dato | I15: Descripción | J15: Tipo de Dato | K15: Descripción | O15: Política | P15: Descripción | Q15: Detalle | R15: ¿Qué hago?
A16: =HYPERLINK("#'C-Pais'!W4","buscarPaisPorFiltro") -> buscarPaisPorFiltro | C16: Permite buscar un país determinado por un criterio específico (nombre, id) | G16: filtro | H16: Pais | I16: Contiene la información de los filtros que servirán como base para llevar a cabo la consulta de la información | J16: Lista<Pais> | K16: Contiene la información de todos los países que cumplen con el filtro de consulta | O16: =HYPERLINK("#'P-Pais'!A5",'P-Pais'!A5) -> P-PAI-001 | P16: ='P-Pais'!B5 -> Asegurar que los datos requeridos sean válidos en tipo de dato, longitud, obligatoriedad y formato | Q16: Informar con un mensaje de error si ocurre un fallo al recuperar el catálogo de países | R16: Detener operación

Sheet E-Pais
A1: <<<Ir al modelo de dominio | B1: <<<Ir a objeto de dominio | C1: <<<Ir a muestreo del objeto | D1: <<<Ir a caracterización | E1: Ir a las políticas>>>
A2: Objeto de Dominio: | B2: ='Objetos de Dominio'!A3 -> Pais
A3: Descripción: | B3: ='Objetos de Dominio'!B3 -> Representa el país al que pertenecen las sedes.
A4: Actor | B4: Action/Command | D4: Entity/Aggregate/ Object domain | E4: Read Model | G4: Business Rule/Policy | I4: External System | J4: Domain Event | K4: Hotspot/questions/Risk
A5: Actor | B5: Acción | C5: Descripción | D5: Objeto de dominio | E5: Información externa | G5: Políticas | I5: Sistema Externo | J5: Evento | K5: Aspectos por solucionar
E6: Información | F6: Descripción | G6: Número | H6: Descripción
A7: Administrador / Vendedor | B7: Buscar país por filtro | C7: Permite buscar un país determinado por un criterio específico (nombre, id) | D7: =$B$2 -> Pais | E7: Filtros de paises | F7: Los parámetros de búsqueda ingresados por el usuario para filtrar el catálogo | G7: =HYPERLINK("#'P-Pais'!A5",'P-Pais'!A5) -> P-PAI-001 | H7: ='P-Pais'!B5 -> Asegurar que los datos requeridos sean válidos en tipo de dato, longitud, obligatoriedad y formato | J7: Paises encontrados

Sheet P-Pais
A1: <<<Ir al modelo de dominio | B1: <<<Ir a objeto de dominio | C1: <<<Ir a muestreo del objeto | D1: <<<Ir a caracterización | E1: <<<Ir al event storming
A2: Objeto de Dominio: | B2: ='Objetos de Dominio'!A3 -> Pais
A3: Descripción: | B3: ='Objetos de Dominio'!B3 -> Representa el país al que pertenecen las sedes.
A4: Número Política | B4: Descripción Política | C4: Objeto Responsable
A5: P-PAI-001 | B5: Asegurar que los datos requeridos sean válidos en tipo de dato, longitud, obligatoriedad y formato | C5: =$B$2 -> Pais

Sheet M-MetodoPago
A1: <<<Ir al modelo de dominio | B1: <<<Ir a objeto de dominio | C1: Ir a la caracterización>>> | D1: Ir al event storming>>> | E1: Ir a las políticas>>>
A2: Nombre: | B2: ='Objetos de Dominio'!A4 -> MetodoPago
A3: Descripción: | B3: ='Objetos de Dominio'!B4 -> Representa las formas en que un cliente puede cancelar una compra (efectivo, tarjeta, transferencia, Nequi, entre otras).
A4: Identificador único del método de pago | B4: Nombre del método de pago disponible en el negocio | C4: Indica si el método de pago está disponible para utilizarse | D4: Combinación única que indica que no puede existir más de un método de pago con el mismo nombre
A5: ID | B5: Nombre | C5: EsActivo | D5: MetodoUnico
A6: 1 | B6: Efectivo | C6: SI | D6: =B6 -> Efectivo
A7: 2 | B7: Tarjeta Débito | C7: SI | D7: =B7 -> Tarjeta Débito
A8: 3 | B8: Tarjeta Crédito | C8: SI | D8: =B8 -> Tarjeta Crédito
A9: 4 | B9: Nequi | C9: SI | D9: =B9 -> Nequi
A10: 5 | B10: Transferencia Bancaria | C10: SI | D10: =B10 -> Transferencia Bancaria
A11: 7 | B11: Wompi | C11: NO | D11: =B11 -> Wompi

Sheet C-MetodoPago
A1: <<<Ir al modelo de dominio | B1: <<<Ir a objeto de dominio | C1: <<<Ir a muestreo del objeto | D1: Ir al event storming>>> | E1: Ir a las políticas>>>
A2: Nombre | B2: ='Objetos de Dominio'!A4 -> MetodoPago
A3: Descripción | B3: ='Objetos de Dominio'!B4 -> Representa las formas en que un cliente puede cancelar una compra (efectivo, tarjeta, transferencia, Nequi, entre otras).
A4: Nombre atributo | B4: Descripción atributo | C4: Identificador del objeto de dominio | D4: Tipo de dato | E4: Obligatorio | F4: Longitud mínima (si aplica) | G4: Longitud máxima (si aplica) | H4: Precisión (si aplica) | I4: Redondeo (si aplica) | J4: Rango inicial (si aplica) | K4: Rango final (si aplica) | L4: Formato (si aplica) | M4: Reglas especiales (si aplica) | N4: Dato calculado | O4: Aplica ajuste del dato (si aplica) | P4: Carácter de ajuste (si aplica) | Q4: Quitar espacios en blanco al inicio (si aplica) | R4: Quitar espacios en blanco al fin (si aplica) | S4: Dato sensible (si aplica) | T4: Valor por defecto (si aplica) | U4: Auto generado | V4: =HYPERLINK("#'C-MetodoPago'!A17","registrarMetodoPago") -> registrarMetodoPago | W4: consultarMetodosPagoPorFiltro
A5: ID | B5: ='M-MetodoPago'!A4 -> Identificador único del método de pago | C5: Si | D5: Identificador único universal | E5: Si | F5: - | G5: - | H5: - | I5: - | J5: - | K5: - | L5: - | M5: Debe ser único y no debe repetirse en los distintos id's de los métodos de pago | N5: No | O5: No | P5: - | Q5: No | R5: No | S5: - | T5: - | U5: Si | V5: Requerido | W5: Filtro | X5: No Mostrar
A6: Nombre | B6: ='M-MetodoPago'!B4 -> Nombre del método de pago disponible en el negocio | C6: No | D6: Texto | E6: Si | F6: 2 | G6: 50 | H6: - | I6: - | J6: - | K6: - | L6: - | M6: Se debe asegurar una sanitización del dato, para garantizar que dentro de su contenido no tenga cualquier tipo de intento de ataque | N6: No | O6: No | P6: - | Q6: Si | R6: Si | S6: - | T6: - | U6: No | V6: Requerido | W6: Filtro | X6: Mostrar
A7: EsActivo | B7: ='M-MetodoPago'!C4 -> Indica si el método de pago está disponible para utilizarse | C7: No | D7: Lógico | E7: Si | F7: - | G7: - | H7: - | I7: - | J7: - | K7: - | L7: - | M7: Solo admite SI o NO y es ingresado por el administrador; al pasar a NO el registro se inhabilita pero se conserva su historial | N7: No | O7: No | P7: - | Q7: No | R7: No | S7: - | T7: - | U7: No | V7: Requerido | W7: Filtro | X7: Mostrar
A10: Nombre combinación única | B10: Descripción | C10: Atributos involucrados
A11: ='M-MetodoPago'!D5 -> MetodoUnico | B11: ='M-MetodoPago'!D4 -> Combinación única que indica que no puede existir más de un método de pago con el mismo nombre | C11: Nombre
A15: Responsabilidad | C15: Descripción | G15: Entradas | J15: Salida | O15: Políticas (Reglas de Negocio) | Q15: Excepción
G16: Parámetro | H16: Tipo de dato | I16: Descripción | J16: Tipo de Dato | K16: Descripción | O16: Política | P16: Descripción | Q16: Detalle | R16: ¿Qué hago?
A17: =HYPERLINK("#'C-MetodoPago'!V4","registrarMetodoPago") -> registrarMetodoPago | C17: Permite agregar una nueva opción al catálogo de métodos de pago del sistema | G17: datos | H17: MetodoPago | I17: Corresponde al nombre y estado del nuevo método de pago | J17: MetodoPago | K17: Objeto del método de pago registrado con su nombre y su estado correspondiente | O17: =HYPERLINK("#'P-MetodoPago'!A5",'P-MetodoPago'!A5) -> P-MDP-001 | P17: ='P-MetodoPago'!B5 -> Asegurar que el id del metodo de pago sea único e irrepetible | Q17: Generar un nuevo identificador hasta garantizar que no exista | R17: Continuar operación
O18: =HYPERLINK("#'P-MetodoPago'!A6",'P-MetodoPago'!A6) -> P-MDP-002 | P18: ='P-MetodoPago'!B6 -> Asegurar que el nombre del método sea único e irrepetible | Q18: Generar una excepción indicando que ya existe un metodo de pago registrado con ese nombre | R18: Detener operación
O19: =HYPERLINK("#'P-MetodoPago'!A7",'P-MetodoPago'!A7) -> P-MDP-003 | P19: ='P-MetodoPago'!B7 -> Asegurar que los datos requeridos sean válidos en tipo de dato, longitud, obligatoriedad y formato | Q19: Informar con un mensaje de error si los parámetros de consulta son inválidos | R19: Detener operación
A20: =HYPERLINK("#'C-MetodoPago'!X4","consultarMetodosPagoPorFiltro") -> consultarMetodosPagoPorFiltro | C20: Permite buscar por filtro y visualizar los métodos de pago habilitados para realizar transacciones | G20: filtro | H20: MetodoPago | I20: Los parámetros de búsqueda ingresados por el usuario para filtrar el catálogo | J20: Lista<MetodoPago> | K20: Contiene la lista de métodos de pago que cumplen con las condiciones del filtro enviado | O20: =HYPERLINK("#'P-MetodoPago'!A7",'P-MetodoPago'!A7) -> P-MDP-003 | P20: ='P-MetodoPago'!B7 -> Asegurar que los datos requeridos sean válidos en tipo de dato, longitud, obligatoriedad y formato | Q20: Informar con un mensaje de error si los parámetros de filtro de consulta son inválidos | R20: Detener operación

Sheet E-MetodoPago
A1: <<<Ir al modelo de dominio | B1: <<<Ir a objeto de dominio | C1: <<<Ir a muestreo del objeto | D1: <<<Ir a caracterización | E1: Ir a las políticas>>>
A2: Objeto de Dominio: | B2: ='Objetos de Dominio'!A4 -> MetodoPago
A3: Descripción: | B3: ='Objetos de Dominio'!B4 -> Representa las formas en que un cliente puede cancelar una compra (efectivo, tarjeta, transferencia, Nequi, entre otras).
A4: Actor | B4: Action/Command | D4: Entity/Aggregate/Object domain | E4: Read Model | G4: Business Rule/Policy | I4: External System | J4: Domain Event | K4: Hotspot/questions/Risk
A5: Actor | B5: Acción | C5: Descripción | D5: Objeto de dominio | E5: Información externa | G5: Políticas | I5: Sistema Externo | J5: Evento | K5: Aspectos por solucionar
E6: Información | F6: Descripción | G6: Número | H6: Descripción
A7: Administrador | B7: Registrar un nuevo método de pago | C7: Permite agregar una nueva opción al catálogo de métodos de pago del sistema | D7: MetodoPago | E7: Datos del método de pago | F7: Corresponde al nombre y estado del nuevo método de pago | G7: =HYPERLINK("#'P-MetodoPago'!A5",'P-MetodoPago'!A5) -> P-MDP-001 | H7: ='P-MetodoPago'!B5 -> Asegurar que el id del metodo de pago sea único e irrepetible | J7: Método de pago registrado
G8: =HYPERLINK("#'P-MetodoPago'!A6",'P-MetodoPago'!A6) -> P-MDP-002 | H8: ='P-MetodoPago'!B6 -> Asegurar que el nombre del método sea único e irrepetible
G9: =HYPERLINK("#'P-MetodoPago'!A7",'P-MetodoPago'!A7) -> P-MDP-003 | H9: ='P-MetodoPago'!B7 -> Asegurar que los datos requeridos sean válidos en tipo de dato, longitud, obligatoriedad y formato
A10: Administrador/Vendedor | B10: Buscar método por criterio | C10: Permite buscar por filtro y visualizar los métodos de pago habilitados para realizar transacciones | D10: MetodoPago | E10: Filtros de los metodos de pago | F10: Los parámetros de búsqueda ingresados por el usuario para filtrar el catálogo | G10: =HYPERLINK("#'P-MetodoPago'!A7",'P-MetodoPago'!A7) -> P-MDP-003 | H10: ='P-MetodoPago'!B7 -> Asegurar que los datos requeridos sean válidos en tipo de dato, longitud, obligatoriedad y formato | J10: Métodos de pago encontrados

Sheet P-MetodoPago
A1: <<<Ir al modelo de dominio | B1: <<<Ir a objeto de dominio | C1: <<<Ir a muestreo del objeto | D1: <<<Ir a caracterización | E1: <<<Ir al event storming
A2: Objeto de Dominio: | B2: ='Objetos de Dominio'!A4 -> MetodoPago
A3: Descripción: | B3: ='Objetos de Dominio'!B4 -> Representa las formas en que un cliente puede cancelar una compra (efectivo, tarjeta, transferencia, Nequi, entre otras).
A4: Número Política | B4: Descripción Política | C4: Objeto Responsable
A5: P-MDP-001 | B5: Asegurar que el id del metodo de pago sea único e irrepetible | C5: MetodoPago
A6: P-MDP-002 | B6: Asegurar que el nombre del método sea único e irrepetible | C6: MetodoPago
A7: P-MDP-003 | B7: Asegurar que los datos requeridos sean válidos en tipo de dato, longitud, obligatoriedad y formato | C7: MetodoPago

Sheet M-Cliente
A1: <<<Ir al modelo de dominio | B1: <<<Ir a objeto de dominio | C1: Ir a la caracterización>>> | D1: Ir al event storming>>> | E1: Ir a las políticas>>>
A2: Nombre: | B2: ='Objetos de Dominio'!A5 -> Cliente
A3: Descripción: | B3: ='Objetos de Dominio'!B5 -> Representa a la persona que adquiere productos en cualquiera de las sedes del negocio.
A4: Identificador único del cliente | B4: Indica si la compra debe asociarse al cliente no registrado cuando el comprador no se desea ser registrado en el sistema.
A5: ID | B5: ClientePorDefecto
A6: 1 | B6: SI
A7: 2 | B7: NO
A8: 3 | B8: NO
A9: 4 | B9: SI
A10: 5 | B10: NO
A11: 6 | B11: SI

Sheet C-Cliente
A1: <<<Ir al modelo de dominio | B1: <<<Ir a objeto de dominio | C1: <<<Ir a muestreo del objeto | D1: Ir al event storming>>> | E1: Ir a las políticas>>>
A2: Nombre | B2: ='Objetos de Dominio'!A5 -> Cliente
A3: Descripción | B3: ='Objetos de Dominio'!B5 -> Representa a la persona que adquiere productos en cualquiera de las sedes del negocio.
A4: Nombre atributo | B4: Descripción atributo | C4: Identificador del objeto de dominio | D4: Tipo de dato | E4: Obligatorio | F4: Longitud mínima (si aplica) | G4: Longitud máxima (si aplica) | H4: Precisión (si aplica) | I4: Redondeo (si aplica) | J4: Rango inicial (si aplica) | K4: Rango final (si aplica) | L4: Formato (si aplica) | M4: Reglas especiales (si aplica) | N4: Dato calculado | O4: Aplica ajuste del dato (si aplica) | P4: Carácter de ajuste (si aplica) | Q4: Quitar espacios en blanco al inicio (si aplica) | R4: Quitar espacios en blanco al fin (si aplica) | S4: Dato sensible (si aplica) | T4: Valor por defecto (si aplica) | U4: Auto generado | V4: =HYPERLINK("#'C-Cliente'!A11","registrarCliente") -> registrarCliente | W4: consultarClientesPorFiltro | Y4: =HYPERLINK("#'C-Cliente'!A14","eliminarCliente") -> eliminarCliente
A5: ID | B5: ='M-Cliente'!A4 -> Identificador único del cliente | C5: Si | D5: Identificador único universal | E5: Si | F5: - | G5: - | H5: - | I5: - | J5: - | K5: - | L5: - | M5: Debe ser único y no debe repetirse en los distintos id's de los clientes | N5: No | O5: No | P5: - | Q5: No | R5: No | S5: - | T5: - | U5: Si | V5: Requerido | W5: Filtro | X5: No mostrar | Y5: Requerido
A6: ClientePorDefecto | B6: ='M-Cliente'!B4 -> Indica si la compra debe asociarse al cliente no registrado cuando el comprador no se desea ser registrado en el sistema. | C6: Si | D6: Lógico | E6: Si | F6: - | G6: - | H6: - | I6: - | J6: - | K6: - | L6: - | M6: Solo admite SI o NO y es ingresado por el administrador; al pasar a NO el registro no se realiza pero se conserva su historial | N6: No | O6: No | P6: - | Q6: No | R6: No | S6: - | T6: - | U6: No | V6: Requerido | W6: Filtro | X6: Mostrar | Y6: No requerido
A9: Responsabilidades | C9: Descripción | G9: Entradas | J9: Salida | O9: Políticas (Reglas de Negocio) | Q9: Excepción
G10: Parámetro | H10: Tipo de dato | I10: Descripción | J10: Tipo de Dato | K10: Descripción | O10: Política | P10: Descripción | Q10: Detalle | R10: ¿Qué hago?
A11: =HYPERLINK("#'C-Cliente'!V4","registrarCliente") -> registrarCliente | C11: Crea el registro base del cliente asignando un ID universal y definiendo si es el cliente por defecto | G11: datos | H11: Cliente | I11: Contiene la información requerida para registrar el cliente | J11: Cliente | K11: Objeto del cliente registrado con su identificador ID asignado y estados por defecto | O11: =HYPERLINK("#'P-Cliente'!A5",'P-Cliente'!A5) -> P-CLI-001 | P11: ='P-Cliente'!B5 -> Asegurar que el id del cliente sea único e irrepetible | Q11: Generar un nuevo identificador hasta garantizar que no exista | R11: Continuar operación
O12: =HYPERLINK("#'P-Cliente'!A6",'P-Cliente'!A6) -> P-CLI-002 | P12: ='P-Cliente'!B6 -> Asegurar que los datos requeridos sean válidos en tipo de dato, longitud, obligatoriedad y formato | Q12: Generar una excepción indicando que los datos requeridos son inválidos o están incompletos | R12: Detener operación
A13: =HYPERLINK("#'C-Cliente'!X4","consultarClientesPorFiltro") -> consultarClientesPorFiltro | C13: Los parámetros de búsqueda ingresados por el usuario para filtrar la lista de clientes | G13: filtro | H13: Cliente | I13: Contiene los parámetros o criterios de consulta enviados para filtrar la búsqueda | J13: Lista<Cliente> | K13: Contiene la lista de clientes que cumplen con las condiciones del filtro enviado | O13: =HYPERLINK("#'P-Cliente'!A6",'P-Cliente'!A6) -> P-CLI-002 | P13: ='P-Cliente'!B6 -> Asegurar que los datos requeridos sean válidos en tipo de dato, longitud, obligatoriedad y formato | Q13: Generar una excepción indicando que los datos requeridos son inválidos o están incompletos | R13: Detener operación
A14: eliminarCliente | C14: Permite eliminar un cliente, borrando todo su historial de compras y de devoluciones, solo si el cliente registrado lo desea | G14: id | H14: UUID | I14: Contiene el identificador único del cliente que se desea eliminar | O14: =HYPERLINK("#'P-Cliente'!A7",'P-Cliente'!A7) -> P-CLI-003 | P14: ='P-Cliente'!B7 -> Asegurar que el cliente no esté siendo utilizado dentro de otro objeto de dominio | Q14: Generar una excepción indicando al usuario que el cliente está siendo usado por otros tipos de cliente (cliente registrado o no registrado) | R14: Detener operación

Sheet E-Cliente
A1: <<<Ir al modelo de dominio | B1: <<<Ir a objeto de dominio | C1: <<<Ir a muestreo del objeto | D1: <<<Ir a caracterización | E1: Ir a las políticas>>>
A2: Objeto de Dominio: | B2: ='Objetos de Dominio'!A5 -> Cliente
A3: Descripción: | B3: ='Objetos de Dominio'!B5 -> Representa a la persona que adquiere productos en cualquiera de las sedes del negocio.
A4: Actor | B4: Action/Command | D4: Entity/Aggregate/Object domain | E4: Read Model | G4: Business Rule/Policy | I4: External System | J4: Domain Event | K4: Hotspot/questions/Risk
A5: Actor | B5: Acción | C5: Descripción | D5: Objeto de dominio | E5: Información externa | G5: Políticas | I5: Sistema Externo | J5: Evento | K5: Aspectos por solucionar
E6: Información | F6: Descripción | G6: Número | H6: Descripción
A7: Administrador/Vendedor | B7: Registrar un nuevo cliente | C7: Crea el registro base del cliente asignando un ID universal y definiendo si es el cliente por defecto | D7: Cliente | E7: Datos del nuevo cliente | F7: Corresponde a la asignación interna del id del cliente y el registro de su tipo | G7: =HYPERLINK("#'P-Cliente'!A5",'P-Cliente'!A5) -> P-CLI-001 | H7: ='P-Cliente'!B5 -> Asegurar que el id del cliente sea único e irrepetible | J7: Cliente registrado
G8: =HYPERLINK("#'P-Cliente'!A6",'P-Cliente'!A6) -> P-CLI-002 | H8: ='P-Cliente'!B6 -> Asegurar que los datos requeridos sean válidos en tipo de dato, longitud, obligatoriedad y formato
A9: Administrador/Vendedor | B9: Buscar cliente por criterio | C9: Permite buscar por filtro y visualizar los clientes disponibles para realizar compras | D9: Cliente | E9: Filtros del id y estados de cliente | F9: Los parámetros de búsqueda ingresados por el usuario para filtrar el cliente | G9: =HYPERLINK("#'P-Cliente'!A6",'P-Cliente'!A6) -> P-CLI-002 | H9: ='P-Cliente'!B6 -> Asegurar que los datos requeridos sean válidos en tipo de dato, longitud, obligatoriedad y formato | J9: Clientes encontrados
A10: Administrador | B10: Eliminar cliente | C10: Permite eliminar el registro de un cliente del catálogo del sistema | D10: Cliente | E10: Datos cliente(id) | F10: Identificador único del cliente que se desea retirar o inactivar | G10: =HYPERLINK("#'P-Cliente'!A6",'P-Cliente'!A6) -> P-CLI-002 | H10: ='P-Cliente'!B6 -> Asegurar que los datos requeridos sean válidos en tipo de dato, longitud, obligatoriedad y formato | J10: Cliente eliminado
G11: =HYPERLINK("#'P-Cliente'!A7",'P-Cliente'!A7) -> P-CLI-003 | H11: ='P-Cliente'!B7 -> Asegurar que el cliente no esté siendo utilizado dentro de otro objeto de dominio

Sheet P-Cliente
A1: <<<Ir al modelo de dominio | B1: <<<Ir a objeto de dominio | C1: <<<Ir a muestreo del objeto | D1: <<<Ir a caracterización | E1: <<<Ir al event storming
A2: Objeto de Dominio: | B2: ='Objetos de Dominio'!A5 -> Cliente
A3: Descripción: | B3: ='Objetos de Dominio'!B5 -> Representa a la persona que adquiere productos en cualquiera de las sedes del negocio.
A4: Número Política | B4: Descripción Política | C4: Objeto Responsable
A5: P-CLI-001 | B5: Asegurar que el id del cliente sea único e irrepetible | C5: Cliente
A6: P-CLI-002 | B6: Asegurar que los datos requeridos sean válidos en tipo de dato, longitud, obligatoriedad y formato | C6: Cliente
A7: P-CLI-003 | B7: Asegurar que el cliente no esté siendo utilizado dentro de otro objeto de dominio | C7: Cliente

Sheet M-Marca
A1: <<<Ir al modelo de dominio | B1: <<<Ir a objeto de dominio | C1: Ir a la caracterización>>> | D1: Ir al event storming>>> | E1: Ir a las políticas>>>
A2: Nombre: | B2: ='Objetos de Dominio'!A6 -> Marca
A3: Descripción: | B3: ='Objetos de Dominio'!B6 -> Representa al fabricante de los accesorios y repuestos que comercializa el negocio.
A4: Identificador único de la marca | B4: Nombre del fabricante de los productos | C4: Variable booleana que define si una marca específica sigue siendo usada en la empresa | D4: Combinación única que indica que no puede existir más de una marca con el mismo nombre
A5: ID | B5: Nombre | C5: EsActivo | D5: MarcaUnica
A6: 1 | B6: Samsung | C6: SI | D6: =B6 -> Samsung
A7: 2 | B7: Apple | C7: SI | D7: =B7 -> Apple
A8: 3 | B8: Xiaomi | C8: SI | D8: =B8 -> Xiaomi
A9: 4 | B9: Saiya | C9: NO | D9: =B9 -> Saiya
A10: 5 | B10: Batri | C10: SI | D10: =B10 -> Batri
A11: 6 | B11: iGoma | C11: SI | D11: =B11 -> iGoma
A12: 7 | B12: SpaceX | C12: NO | D12: =B12 -> SpaceX

Sheet C-Marca
A1: <<<Ir al modelo de dominio | B1: <<<Ir a objeto de dominio | C1: <<<Ir a muestreo del objeto | D1: Ir al event storming>>> | E1: Ir a las políticas>>>
A2: Nombre | B2: ='Objetos de Dominio'!A6 -> Marca
A3: Descripción | B3: ='Objetos de Dominio'!B6 -> Representa al fabricante de los accesorios y repuestos que comercializa el negocio.
A4: Nombre atributo | B4: Descripción atributo | C4: Identificador del objeto de dominio | D4: Tipo de dato | E4: Obligatorio | F4: Longitud mínima (si aplica) | G4: Longitud máxima (si aplica) | H4: Precisión (si aplica) | I4: Redondeo (si aplica) | J4: Rango inicial (si aplica) | K4: Rango final (si aplica) | L4: Formato (si aplica) | M4: Reglas especiales (si aplica) | N4: Dato calculado | O4: Aplica ajuste del dato (si aplica) | P4: Carácter de ajuste (si aplica) | Q4: Quitar espacios en blanco al inicio (si aplica) | R4: Quitar espacios en blanco al fin (si aplica) | S4: Dato sensible (si aplica) | T4: Valor por defecto (si aplica) | U4: Auto generado | V4: registrarMarca | W4: =HYPERLINK("#'C-Marca'!A20","consultarMarcasPorFiltro") -> consultarMarcasPorFiltro
A5: ID | B5: ='M-Marca'!A4 -> Identificador único de la marca | C5: Si | D5: Identificador único universal | E5: Si | F5: - | G5: - | H5: - | I5: - | J5: - | K5: - | L5: - | M5: Debe ser único y no debe repetirse en los distintos id's de las marcas | N5: No | O5: No | P5: - | Q5: No | R5: No | S5: - | T5: - | U5: Si | V5: Requerido | W5: Filtro | X5: No mostrar
A6: Nombre | B6: ='M-Marca'!B4 -> Nombre del fabricante de los productos | C6: No | D6: Alfanumérico | E6: Si | F6: 2 | G6: 50 | H6: - | I6: - | J6: - | K6: - | L6: - | M6: Se debe asegurar una sanitización del dato, para garantizar que dentro de su contenido no tenga cualquier tipo de intento de ataque | N6: No | O6: No | P6: - | Q6: Si | R6: Si | S6: - | T6: - | U6: No | V6: Requerido | W6: Filtro | X6: Mostrar
A7: EsActivo | B7: ='M-Marca'!C4 -> Variable booleana que define si una marca específica sigue siendo usada en la empresa | C7: No | D7: Lógico | E7: Si | F7: - | G7: - | H7: - | I7: - | J7: - | K7: - | L7: - | M7: Solo admite SI o NO y es ingresado por el administrador; al pasar a NO la marca se inhabilita pero se conserva su historial | N7: No | O7: No | P7: - | Q7: No | R7: No | S7: - | T7: No | U7: No | V7: Requerido | W7: Filtro | X7: Mostrar
A10: Nombre combinación única | B10: Descripción | C10: Atributos involucrados
A11: ='M-Marca'!D5 -> MarcaUnica | B11: ='M-Marca'!D4 -> Combinación única que indica que no puede existir más de una marca con el mismo nombre | C11: Nombre
A15: Responsabilidad | C15: Descripción | G15: Entradas | J15: Salida | O15: Políticas (Reglas de Negocio) | Q15: Excepción
G16: Parámetro | H16: Tipo de dato | I16: Descripción | J16: Tipo de Dato | K16: Descripción | O16: Política | P16: Descripción | Q16: Detalle | R16: ¿Qué hago?
A17: =HYPERLINK("#'C-Marca'!V4","registrarMarca") -> registrarMarca | C17: Permite ingresar una nueva marca en el catálogo general del sistema | G17: datos | H17: Marca | I17: Contiene la información requerida para registrar la marca | J17: Marca | K17: Objeto de la marca registrada con su nombre y estado correspondiente | O17: =HYPERLINK("#'P-Marca'!A5",'P-Marca'!A5) -> P-MAR-001 | P17: ='P-Marca'!B5 -> Asegurar que el id de marca sea único e irrepetible | Q17: Generar un nuevo identificador hasta garantizar que no exista | R17: Continuar operación
O18: =HYPERLINK("#'P-Marca'!A6",'P-Marca'!A6) -> P-MAR-002 | P18: ='P-Marca'!B6 -> Asegurar que el nombre de la marca sea único e irrepetible | Q18: Generar una excepción indicando que ya existe una marca con ese nombre | R18: Detener operación
O19: =HYPERLINK("#'P-Marca'!A7",'P-Marca'!A7) -> P-MAR-003 | P19: ='P-Marca'!B7 -> Asegurar que los datos requeridos sean válidos en tipo de dato, longitud, obligatoriedad y formato | Q19: Generar una excepción indicando que los datos requeridos son inválidos o están incompletos | R19: Detener operación
A20: =HYPERLINK("#'C-Marca'!X4","consultarMarcasPorFiltro") -> consultarMarcasPorFiltro | C20: Permite buscar, listar y filtrar el catálogo de marcas por nombre, identificador ID o estado | G20: filtro | H20: Marca | I20: Contiene los parámetros o criterios de búsqueda enviados para filtrar la consulta | J20: Lista<Marca> | K20: Contiene la lista de marcas que cumplen con las condiciones del filtro enviado | O20: =HYPERLINK("#'P-Marca'!A7",'P-Marca'!A7) -> P-MAR-003 | P20: ='P-Marca'!B7 -> Asegurar que los datos requeridos sean válidos en tipo de dato, longitud, obligatoriedad y formato | Q20: Generar una excepción indicando que los datos requeridos son inválidos o están incompletos | R20: Detener operación

Sheet E-Marca
A1: <<<Ir al modelo de dominio | B1: <<<Ir a objeto de dominio | C1: <<<Ir a muestreo del objeto | D1: <<<Ir a caracterización | E1: Ir a las políticas>>>
A2: Objeto de Dominio: | B2: ='Objetos de Dominio'!A6 -> Marca
A3: Descripción: | B3: ='Objetos de Dominio'!B6 -> Representa al fabricante de los accesorios y repuestos que comercializa el negocio.
A4: Actor | B4: Action/Command | D4: Entity/Aggregate/Object domain | E4: Read Model | G4: Business Rule/Policy | I4: External System | J4: Domain Event | K4: Hotspot/questions/Risk
A5: Actor | B5: Acción | C5: Descripción | D5: Objeto de dominio | E5: Información externa | G5: Políticas | I5: Sistema Externo | J5: Evento | K5: Aspectos por solucionar
E6: Información | F6: Descripción | G6: Número | H6: Descripción
A7: Administrador | B7: Registrar una nueva marca | C7: Permite ingresar una nueva marca en el catálogo del sistema | D7: Marca | E7: Datos de la nueva marca | F7: Corresponde al nombre comercial y estado de actividad de la marca | G7: =HYPERLINK("#'P-Marca'!A5",'P-Marca'!A5) -> P-MAR-001 | H7: ='P-Marca'!B5 -> Asegurar que el id de marca sea único e irrepetible | J7: Marca registrada
G8: =HYPERLINK("#'P-Marca'!A6",'P-Marca'!A6) -> P-MAR-002 | H8: ='P-Marca'!B6 -> Asegurar que el nombre de la marca sea único e irrepetible
G9: =HYPERLINK("#'P-Marca'!A7",'P-Marca'!A7) -> P-MAR-003 | H9: ='P-Marca'!B7 -> Asegurar que los datos requeridos sean válidos en tipo de dato, longitud, obligatoriedad y formato
A10: Administrador/Vendedor | B10: Consultar marca por filtro | C10: Permite buscar una marca por un criterio específico | D10: Marca | E10: Datos de la marca(Id, Nombre y esActivo) | F10: Los parámetros de búsqueda ingresados por el usuario para filtrar la marca | G10: =HYPERLINK("#'P-Marca'!A7",'P-Marca'!A7) -> P-MAR-003 | H10: ='P-Marca'!B7 -> Asegurar que los datos requeridos sean válidos en tipo de dato, longitud, obligatoriedad y formato | J10: Marcas encontradas

Sheet P-Marca
A1: <<<Ir al modelo de dominio | B1: <<<Ir a objeto de dominio | C1: <<<Ir a muestreo del objeto | D1: <<<Ir a caracterización | E1: <<<Ir al event storming
A2: Objeto de Dominio: | B2: ='Objetos de Dominio'!A6 -> Marca
A3: Descripción: | B3: ='Objetos de Dominio'!B6 -> Representa al fabricante de los accesorios y repuestos que comercializa el negocio.
A4: Número Política | B4: Descripción Política | C4: Objeto Responsable
A5: P-MAR-001 | B5: Asegurar que el id de marca sea único e irrepetible | C5: Marca
A6: P-MAR-002 | B6: Asegurar que el nombre de la marca sea único e irrepetible | C6: Marca
A7: P-MAR-003 | B7: Asegurar que los datos requeridos sean válidos en tipo de dato, longitud, obligatoriedad y formato | C7: Marca

Sheet M-Motivo
A1: <<<Ir al modelo de dominio | B1: <<<Ir a objeto de dominio | C1: Ir a la caracterización>>> | D1: Ir al event storming>>> | E1: Ir a las políticas>>>
A2: Nombre: | B2: ='Objetos de Dominio'!A7 -> Motivo
A3: Descripción: | B3: ='Objetos de Dominio'!B7 -> Representa la razón por la que un cliente solicita devolver un producto.
A4: Identificador único del motivo | B4: Nombre que representa el motivo de devolución | C4: Combinación única que indica que no puede existir más de una motivo con el mismo nombre
A5: ID | B5: Nombre | C5: MotivoUnico
A6: 1 | B6: Garantía | C6: =B6 -> Garantía
A7: 2 | B7: Cambio de opinión | C7: =B7 -> Cambio de opinión
A8: 3 | B8: Producto incorrecto | C8: =B8 -> Producto incorrecto
A9: 4 | B9: Referencia incorrecta | C9: =B9 -> Referencia incorrecta
A10: 5 | B10: Otro | C10: =B10 -> Otro

Sheet C-Motivo
A1: <<<Ir al modelo de dominio | B1: <<<Ir a objeto de dominio | C1: <<<Ir a muestreo del objeto | D1: Ir al event storming>>> | E1: Ir a las políticas>>>
A2: Nombre | B2: ='Objetos de Dominio'!A7 -> Motivo
A3: Descripción | B3: ='Objetos de Dominio'!B7 -> Representa la razón por la que un cliente solicita devolver un producto.
A4: Nombre atributo | B4: Descripción atributo | C4: Identificador del objeto de dominio | D4: Tipo de dato | E4: Obligatorio | F4: Longitud mínima (si aplica) | G4: Longitud máxima (si aplica) | H4: Precisión (si aplica) | I4: Redondeo (si aplica) | J4: Rango inicial (si aplica) | K4: Rango final (si aplica) | L4: Formato (si aplica) | M4: Reglas especiales (si aplica) | N4: Dato calculado | O4: Aplica ajuste del dato (si aplica) | P4: Carácter de ajuste (si aplica) | Q4: Quitar espacios en blanco al inicio (si aplica) | R4: Quitar espacios en blanco al fin (si aplica) | S4: Dato sensible (si aplica) | T4: Valor por defecto (si aplica) | U4: Auto generado | V4: consultarPorFiltroMotivos
A5: ID | B5: ='M-Motivo'!A4 -> Identificador único del motivo | C5: Si | D5: Identificador único universal | E5: Si | F5: - | G5: - | H5: - | I5: - | J5: - | K5: - | L5: - | M5: Debe ser único y no repetirse en los distintos id's de los motivos | N5: No | O5: No | P5: - | Q5: No | R5: No | S5: - | T5: - | U5: Si | V5: Filtro | W5: No Mostrar
A6: Nombre | B6: ='M-Motivo'!B4 -> Nombre que representa el motivo de devolución | C6: No | D6: Texto | E6: Si | F6: 4 | G6: 40 | H6: - | I6: - | J6: - | K6: - | L6: - | M6: Se debe asegurar una sanitización del dato, para garantizar que dentro de su contenido no tenga cualquier tipo de intento de ataque | N6: No | O6: No | P6: - | Q6: Si | R6: Si | S6: - | T6: - | U6: No | V6: Filtro | W6: Mostrar
A9: Nombre combinación única | B9: Descripción | C9: Atributos involucrados
A10: ='M-Motivo'!C5 -> MotivoUnico | B10: ='M-Motivo'!C4 -> Combinación única que indica que no puede existir más de una motivo con el mismo nombre | C10: Nombre
A14: Responsabilidad | C14: Descripción | G14: Entradas | J14: Salida | O14: Políticas (Reglas de Negocio) | Q14: Excepción
G15: Parámetro | H15: Tipo de dato | I15: Descripción | J15: Tipo de Dato | K15: Descripción | O15: Política | P15: Descripción | Q15: Detalle | R15: ¿Qué hago?
A16: consultarPorFiltroMotivos | C16: Permite consultar la información por un filtro específico de los motivos registrados en el sistema | G16: filtro | H16: Motivo | I16: Contiene los parámetros o criterios de búsqueda enviados para filtrar la consulta | J16: Lista<Motivo> | K16: Contiene la lista de motivos registrados en el sistema que cumplen con las condicioens del filtro enviado | O16: =HYPERLINK("#'P-Motivo'!A7",'P-Motivo'!A5) -> P-MOT-001 | P16: ='P-Motivo'!B5 -> Asegurar que los datos requeridos sean válidos en tipo de dato, longitud, obligatoriedad y formato | Q16: Informar con un mensaje de error si ocurre un fallo al recuperar la información | R16: Detener operación

Sheet E-Motivo
A1: <<<Ir al modelo de dominio | B1: <<<Ir a objeto de dominio | C1: <<<Ir a muestreo del objeto | D1: <<<Ir a caracterización | E1: Ir a las políticas>>>
A2: Objeto de Dominio: | B2: ='Objetos de Dominio'!A7 -> Motivo
A3: Descripción: | B3: ='Objetos de Dominio'!B7 -> Representa la razón por la que un cliente solicita devolver un producto.
A4: Actor | B4: Action/Command | D4: Entity/Aggregate/Object domain | E4: Read Model | G4: Business Rule/Policy | I4: External System | J4: Domain Event | K4: Hotspot/questions/Risk
A5: Actor | B5: Acción | C5: Descripción | D5: Objeto de dominio | E5: Información externa | G5: Políticas | I5: Sistema Externo | J5: Evento | K5: Aspectos por solucionar
E6: Información | F6: Descripción | G6: Número | H6: Descripción
A7: Administrador/Vendedor | B7: Consultar los motivos por filtro | C7: Permite consultar la información los motivos registrados en el sistema mediante un filtro específico | D7: Motivo | E7: Filtros de los motivos | F7: Contiene la lista de motivos registrados en el sistema | G7: =HYPERLINK("#'P-Motivo'!A5",'P-Motivo'!A5) -> P-MOT-001 | H7: ='P-Motivo'!B5 -> Asegurar que los datos requeridos sean válidos en tipo de dato, longitud, obligatoriedad y formato | J7: Motivos encontrados

Sheet P-Motivo
A1: <<<Ir al modelo de dominio | B1: <<<Ir a objeto de dominio | C1: <<<Ir a muestreo del objeto | D1: <<<Ir a caracterización | E1: <<<Ir al event storming
A2: Objeto de Dominio: | B2: ='Objetos de Dominio'!A7 -> Motivo
A3: Descripción: | B3: ='Objetos de Dominio'!B7 -> Representa la razón por la que un cliente solicita devolver un producto.
A4: Número Política | B4: Descripción Política | C4: Objeto Responsable
A5: P-MOT-001 | B5: Asegurar que los datos requeridos sean válidos en tipo de dato, longitud, obligatoriedad y formato | C5: Motivo

Sheet M-TipoDocumento
A1: <<<Ir al modelo de dominio | B1: <<<Ir a objeto de dominio | C1: Ir a la caracterización>>> | D1: Ir al event storming>>> | E1: Ir a las políticas>>>
A2: Nombre: | B2: ='Objetos de Dominio'!A8 -> TipoDocumento
A3: Descripción: | B3: ='Objetos de Dominio'!B8 -> Representa el tipo de documento de identidad de una persona
A4: Identificador único del documento | B4: Representa el nombre del tipo de documento de identidad de una persona | C4: Combinación única que representa que no puede existir un documento con un mismo nombre
A5: ID | B5: Tipo | C5: DocumentoUnico
A6: 1 | B6: Cédula de ciudadanía | C6: =_xlfn.CONCAT(B6) -> Cédula de ciudadanía
A7: 2 | B7: Cédula de extranjería | C7: =_xlfn.CONCAT(B7) -> Cédula de extranjería
A8: 3 | B8: Tarjeta de identidad | C8: =_xlfn.CONCAT(B8) -> Tarjeta de identidad
A9: 4 | B9: Pasaporte | C9: =_xlfn.CONCAT(B9) -> Pasaporte

Sheet C-TipoDocumento
A1: <<<Ir al modelo de dominio | B1: <<<Ir a objeto de dominio | C1: <<<Ir a muestreo del objeto | D1: Ir al event storming>>> | E1: Ir a las políticas>>>
A2: Nombre | B2: ='Objetos de Dominio'!A8 -> TipoDocumento
A3: Descripción | B3: ='Objetos de Dominio'!B8 -> Representa el tipo de documento de identidad de una persona
A4: Nombre atributo | B4: Descripción atributo | C4: Identificador del objeto de dominio | D4: Tipo de dato | E4: Obligatorio | F4: Longitud mínima (si aplica) | G4: Longitud máxima (si aplica) | H4: Precisión (si aplica) | I4: Redondeo (si aplica) | J4: Rango inicial (si aplica) | K4: Rango final (si aplica) | L4: Formato (si aplica) | M4: Reglas especiales (si aplica) | N4: Dato calculado | O4: Aplica ajuste del dato (si aplica) | P4: Carácter de ajuste (si aplica) | Q4: Quitar espacios en blanco al inicio (si aplica) | R4: Quitar espacios en blanco al fin (si aplica) | S4: Dato sensible (si aplica) | T4: Valor por defecto (si aplica) | U4: Auto generado | V4: =HYPERLINK("#'C-TipoDocumento'!a16","consultarDocumentosPorFiltro") -> consultarDocumentosPorFiltro
A5: ID | B5: ='M-TipoDocumento'!A4 -> Identificador único del documento | C5: Si | D5: Identificador único universal | E5: Si | F5: - | G5: - | H5: - | I5: - | J5: - | K5: - | L5: - | M5: Debe ser único y no repetirse en los distintos id's de documentos | N5: No | O5: No | P5: - | Q5: No | R5: No | S5: - | T5: - | U5: Si | V5: Filtro | W5: No mostrar
A6: Tipo | B6: ='M-TipoDocumento'!B4 -> Representa el nombre del tipo de documento de identidad de una persona | C6: No | D6: Alfanumerico | E6: Si | F6: 9 | G6: 50 | H6: - | I6: - | J6: - | K6: - | L6: - | M6: Se debe asegurar una sanitización del dato, para garantizar que dentro de su contenido no tenga cualquier tipo de intento de ataque | N6: No | O6: No | P6: - | Q6: Si | R6: Si | S6: - | T6: - | U6: No | V6: Filtro | W6: Mostrar
A9: Nombre combinación única | B9: Descripción | C9: Atributos involucrados
A10: ='M-TipoDocumento'!C5 -> DocumentoUnico | B10: ='M-TipoDocumento'!C4 -> Combinación única que representa que no puede existir un documento con un mismo nombre | C10: Tipo
A14: Responsabilidad | C14: Descripción | G14: Entradas | J14: Salida | O14: Políticas (Reglas de Negocio) | Q14: Excepción
G15: Parámetro | H15: Tipo de dato | I15: Descripción | J15: Tipo de Dato | K15: Descripción | O15: Política | P15: Descripción | Q15: Detalle | R15: ¿Qué hago?
A16: =HYPERLINK("#'C-TipoDocumento'!v4","consultarDocumentosPorFiltro") -> consultarDocumentosPorFiltro | C16: Permite consultar los clientes que cumplen con los criterios de búsqueda enviados | G16: filtro | H16: Cliente | I16: Contiene los parámetros o criterios de consulta enviados para filtrar la búsqueda | J16: Lista<TipoDocumento> | K16: Contiene la lista de clientes que cumplen con las condiciones del filtro enviado | O16: ='P-TipoDocumento'!A5 -> P-DOC-001 | P16: ='P-TipoDocumento'!B5 -> Asegurar que los datos requeridos sean válidos en tipo de dato, longitud, obligatoriedad y formato | Q16: Generar una excepción indicando que los datos requeridos son inválidos o están incompletos | R16: Detener operación

Sheet E-TipoDocumento
A1: <<<Ir al modelo de dominio | B1: <<<Ir a objeto de dominio | C1: <<<Ir a muestreo del objeto | D1: <<<Ir a caracterización | E1: Ir a las políticas>>>
A2: Objeto de Dominio: | B2: ='Objetos de Dominio'!A8 -> TipoDocumento
A3: Descripción: | B3: ='Objetos de Dominio'!B8 -> Representa el tipo de documento de identidad de una persona
A4: Actor | B4: Action/Command | D4: Entity/Aggregate/Object domain | E4: Read Model | G4: Business Rule/Policy | I4: External System | J4: Domain Event | K4: Hotspot/questions/Risk
A5: Actor | B5: Acción | C5: Descripción | D5: Objeto de dominio | E5: Información externa | G5: Políticas | I5: Sistema Externo | J5: Evento | K5: Aspectos por solucionar
E6: Información | F6: Descripción | G6: Número | H6: Descripción
A7: Administrador/Vendedor | B7: Consultar documentos por filtro | C7: Permite buscar, listar y filtrar los tipos documentos según los criterios de búsqueda enviados | D7: Documento | E7: Filtros de los tipos de documentos | F7: Contiene los parámetros o criterios de búsqueda enviados para filtrar la consulta | G7: =HYPERLINK("#'P-TipoDocumento'!A5",'P-TipoDocumento'!A5) -> P-DOC-001 | H7: ='P-TipoDocumento'!B5 -> Asegurar que los datos requeridos sean válidos en tipo de dato, longitud, obligatoriedad y formato | J7: Documentos encontrados

Sheet P-TipoDocumento
A1: <<<Ir al modelo de dominio | B1: <<<Ir a objeto de dominio | C1: <<<Ir a muestreo del objeto | D1: <<<Ir a caracterización | E1: <<<Ir al event storming
A2: Objeto de Dominio: | B2: ='Objetos de Dominio'!A8 -> TipoDocumento
A3: Descripción: | B3: ='Objetos de Dominio'!B8 -> Representa el tipo de documento de identidad de una persona
A4: Número Política | B4: Descripción Política | C4: Objeto Responsable
A5: P-DOC-001 | B5: Asegurar que los datos requeridos sean válidos en tipo de dato, longitud, obligatoriedad y formato | C5: TipoDocumento

Sheet M-Categoria
A1: <<<Ir al modelo de dominio | B1: <<<Ir a objeto de dominio | C1: Ir a la caracterización>>> | D1: Ir al event storming>>> | E1: Ir a las políticas>>>
A2: Nombre: | B2: ='Objetos de Dominio'!A9 -> Categoria
A3: Descripción: | B3: ='Objetos de Dominio'!B9 -> Representa la clasificación a la que pertenece un producto dentro del catálogo.
A4: Identificador único de la categoría | B4: Nombre de la clasificación de productos | C4: Identifica la categoría principal o superior a la que pertenece la clasificación correspondiente | D4: Indica el nivel de profundidad jerárquica de la categoría dentro de la estructura del catálogo | E4: Combinación única que indica que no puede existir más de una categoría con el mismo nombre y perteneciendo a la misma categoríaPadre
A5: ID | B5: Nombre | C5: CategoriaPadre | D5: Nivel | E5: CategoriaUnica
A6: 1 | B6: Accesorios | D6: 1 | E6: =_xlfn.CONCAT(B6," || ",C6) -> Accesorios ||
A7: 2 | B7: Estuches/Fundas | C7: =B6 -> Accesorios | D7: 2 | E7: =_xlfn.CONCAT(B7," || ",C7) -> Estuches/Fundas || Accesorios
A8: 3 | B8: Estuches Tablets | C8: =B7 -> Estuches/Fundas | D8: 3 | E8: =_xlfn.CONCAT(B8," || ",C8) -> Estuches Tablets || Estuches/Fundas
A9: 4 | B9: Estuches iPad | C9: =B8 -> Estuches Tablets | D9: 4 | E9: =_xlfn.CONCAT(B9," || ",C9) -> Estuches iPad || Estuches Tablets
A10: 5 | B10: Estuches Lenovo | C10: =B8 -> Estuches Tablets | D10: 4 | E10: =_xlfn.CONCAT(B10," || ",C10) -> Estuches Lenovo || Estuches Tablets
A11: 6 | B11: Estuches Samsung | C11: =B8 -> Estuches Tablets | D11: 4 | E11: =_xlfn.CONCAT(B11," || ",C11) -> Estuches Samsung || Estuches Tablets
A12: 7 | B12: Estuches Huawei | C12: =B8 -> Estuches Tablets | D12: 4 | E12: =_xlfn.CONCAT(B12," || ",C12) -> Estuches Huawei || Estuches Tablets
A13: 8 | B13: Estuches Xiaomi | C13: =B8 -> Estuches Tablets | D13: 4 | E13: =_xlfn.CONCAT(B13," || ",C13) -> Estuches Xiaomi || Estuches Tablets
A14: 9 | B14: Estuches Celulares | C14: =B7 -> Estuches/Fundas | D14: 3 | E14: =_xlfn.CONCAT(B14," || ",C14) -> Estuches Celulares || Estuches/Fundas
A15: 10 | B15: Estuches iPhone | C15: =B14 -> Estuches Celulares | D15: 4 | E15: =_xlfn.CONCAT(B15," || ",C15) -> Estuches iPhone || Estuches Celulares
A16: 11 | B16: Estuches Samsung | C16: =B14 -> Estuches Celulares | D16: 4 | E16: =_xlfn.CONCAT(B16," || ",C16) -> Estuches Samsung || Estuches Celulares
A17: 12 | B17: Estuches Xiaomi | C17: =B14 -> Estuches Celulares | D17: 4 | E17: =_xlfn.CONCAT(B17," || ",C17) -> Estuches Xiaomi || Estuches Celulares
A18: 13 | B18: Estuches Huawei | C18: =B14 -> Estuches Celulares | D18: 4 | E18: =_xlfn.CONCAT(B18," || ",C18) -> Estuches Huawei || Estuches Celulares
A19: 14 | B19: Estuches Motorola | C19: =B14 -> Estuches Celulares | D19: 4 | E19: =_xlfn.CONCAT(B19," || ",C19) -> Estuches Motorola || Estuches Celulares
A20: 15 | B20: Estuches Oppo | C20: =B14 -> Estuches Celulares | D20: 4 | E20: =_xlfn.CONCAT(B20," || ",C20) -> Estuches Oppo || Estuches Celulares
A21: 16 | B21: Estuches Tecno | C21: =B14 -> Estuches Celulares | D21: 4 | E21: =_xlfn.CONCAT(B21," || ",C21) -> Estuches Tecno || Estuches Celulares
A22: 17 | B22: Fundas Portatiles | C22: =B7 -> Estuches/Fundas | D22: 3 | E22: =_xlfn.CONCAT(B22," || ",C22) -> Fundas Portatiles || Estuches/Fundas
A23: 18 | B23: Fundas Apple | C23: =B22 -> Fundas Portatiles | D23: 4 | E23: =_xlfn.CONCAT(B23," || ",C23) -> Fundas Apple || Fundas Portatiles
A24: 19 | B24: Fundas Lenovo | C24: =B22 -> Fundas Portatiles | D24: 4 | E24: =_xlfn.CONCAT(B24," || ",C24) -> Fundas Lenovo || Fundas Portatiles
A25: 20 | B25: Fundas HP | C25: =B22 -> Fundas Portatiles | D25: 4 | E25: =_xlfn.CONCAT(B25," || ",C25) -> Fundas HP || Fundas Portatiles
A26: 21 | B26: Fundas Asus | C26: =B22 -> Fundas Portatiles | D26: 4 | E26: =_xlfn.CONCAT(B26," || ",C26) -> Fundas Asus || Fundas Portatiles
A27: 22 | B27: Fundas Dell | C27: =B22 -> Fundas Portatiles | D27: 4 | E27: =_xlfn.CONCAT(B27," || ",C27) -> Fundas Dell || Fundas Portatiles
A28: 23 | B28: Fundas Samsung | C28: =B22 -> Fundas Portatiles | D28: 4 | E28: =_xlfn.CONCAT(B28," || ",C28) -> Fundas Samsung || Fundas Portatiles
A29: 24 | B29: Vidrios Templados | C29: =B6 -> Accesorios | D29: 2 | E29: =_xlfn.CONCAT(B29," || ",C29) -> Vidrios Templados || Accesorios
A30: 25 | B30: Vidrios Tablets | C30: =B29 -> Vidrios Templados | D30: 3 | E30: =_xlfn.CONCAT(B30," || ",C30) -> Vidrios Tablets || Vidrios Templados
A31: 26 | B31: Vidrios iPad | C31: =B30 -> Vidrios Tablets | D31: 4 | E31: =_xlfn.CONCAT(B31," || ",C31) -> Vidrios iPad || Vidrios Tablets
A32: 27 | B32: Vidrios Lenovo | C32: =B30 -> Vidrios Tablets | D32: 4 | E32: =_xlfn.CONCAT(B32," || ",C32) -> Vidrios Lenovo || Vidrios Tablets
A33: 28 | B33: Vidrios Samsung | C33: =B30 -> Vidrios Tablets | D33: 4 | E33: =_xlfn.CONCAT(B33," || ",C33) -> Vidrios Samsung || Vidrios Tablets
A34: 29 | B34: Vidrios Huawei | C34: =B30 -> Vidrios Tablets | D34: 4 | E34: =_xlfn.CONCAT(B34," || ",C34) -> Vidrios Huawei || Vidrios Tablets
A35: 30 | B35: Vidrios Xiaomi | C35: =B30 -> Vidrios Tablets | D35: 4 | E35: =_xlfn.CONCAT(B35," || ",C35) -> Vidrios Xiaomi || Vidrios Tablets
A36: 31 | B36: Vidrios Celulares | C36: =B29 -> Vidrios Templados | D36: 3 | E36: =_xlfn.CONCAT(B36," || ",C36) -> Vidrios Celulares || Vidrios Templados
A37: 32 | B37: Vidrios iPhone | C37: =B36 -> Vidrios Celulares | D37: 4 | E37: =_xlfn.CONCAT(B37," || ",C37) -> Vidrios iPhone || Vidrios Celulares
A38: 33 | B38: Vidrios Samsung | C38: =B36 -> Vidrios Celulares | D38: 4 | E38: =_xlfn.CONCAT(B38," || ",C38) -> Vidrios Samsung || Vidrios Celulares
A39: 34 | B39: Vidrios Xiaomi | C39: =B36 -> Vidrios Celulares | D39: 4 | E39: =_xlfn.CONCAT(B39," || ",C39) -> Vidrios Xiaomi || Vidrios Celulares
A40: 35 | B40: Vidrios Huawei | C40: =B36 -> Vidrios Celulares | D40: 4 | E40: =_xlfn.CONCAT(B40," || ",C40) -> Vidrios Huawei || Vidrios Celulares
...

Sheet C-Categoria
A1: <<<Ir al modelo de dominio | B1: <<<Ir a objeto de dominio | C1: <<<Ir a muestreo del objeto | D1: Ir al event storming>>> | E1: Ir a las políticas>>>
A2: Nombre | B2: ='Objetos de Dominio'!A9 -> Categoria
A3: Descripción | B3: ='Objetos de Dominio'!B9 -> Representa la clasificación a la que pertenece un producto dentro del catálogo.
A4: Nombre atributo | B4: Descripción atributo | C4: Identificador del objeto de dominio | D4: Tipo de dato | E4: Obligatorio | F4: Longitud mínima (si aplica) | G4: Longitud máxima (si aplica) | H4: Precisión (si aplica) | I4: Redondeo (si aplica) | J4: Rango inicial (si aplica) | K4: Rango final (si aplica) | L4: Formato (si aplica) | M4: Reglas especiales (si aplica) | N4: Dato calculado | O4: Aplica ajuste del dato (si aplica) | P4: Carácter de ajuste (si aplica) | Q4: Quitar espacios en blanco al inicio (si aplica) | R4: Quitar espacios en blanco al fin (si aplica) | S4: Dato sensible (si aplica) | T4: Valor por defecto (si aplica) | U4: Auto generado | V4: registrarCategoria | W4: consultarCategoriasPorFiltro | Y4: modificarCategoria | AA4: eliminarCategoria
A5: ID | B5: ='M-Categoria'!A4 -> Identificador único de la categoría | C5: Si | D5: Identificador único universal | E5: Si | F5: - | G5: - | H5: - | I5: - | J5: - | K5: - | L5: - | M5: Debe ser único y no debe repetirse en los distintos id's de las categorías | N5: No | O5: No | P5: - | Q5: No | R5: No | S5: - | T5: - | U5: Si | V5: Requerido | W5: Filtro | X5: No Mostrar | Y5: Requerido | Z5: No modificable | AA5: Requerido
A6: Nombre | B6: ='M-Categoria'!B4 -> Nombre de la clasificación de productos | C6: No | D6: Alfanumérico | E6: Si | F6: 2 | G6: 50 | H6: - | I6: - | J6: - | K6: - | L6: - | M6: Se debe asegurar una sanitización del dato, para garantizar que dentro de su contenido no tenga cualquier tipo de intento de ataque | N6: No | O6: No | P6: - | Q6: Si | R6: Si | S6: - | T6: - | U6: No | V6: Requerido | W6: Filtro | X6: Mostrar | Y6: Requerido | Z6: Modificable | AA6: No Requerido
A7: CategoriaPadre | B7: ='M-Categoria'!C4 -> Identifica la categoría principal o superior a la que pertenece la clasificación correspondiente | C7: No | D7: Alfanumérico | E7: No | F7: 2 | G7: 50 | H7: - | I7: - | J7: - | K7: - | L7: - | M7: Se debe asegurar una sanitización del dato, para garantizar que dentro de su contenido no tenga cualquier tipo de intento de ataque | N7: No | O7: No | P7: - | Q7: Si | R7: Si | S7: - | T7: Vacio | U7: No | V7: No requerido | W7: Filtro | X7: Mostrar | Y7: No requerido | Z7: Modificable | AA7: No Requerido
A8: Nivel | B8: ='M-Categoria'!D4 -> Indica el nivel de profundidad jerárquica de la categoría dentro de la estructura del catálogo | C8: No | D8: Numérico Entero | E8: Si | F8: - | G8: - | H8: - | I8: - | J8: 1 | K8: - | L8: - | M8: Se calcula a partir de la profundidad de CategoriaPadre + 1; el primer nivel es 1 | N8: Si | O8: No | P8: - | Q8: No | R8: No | S8: - | T8: - | U8: No | V8: No requerido | W8: Filtro | X8: No Mostrar | Y8: No Requerido | Z8: No modificable | AA8: No Requerido
A11: Nombre combinación única | B11: Descripción | C11: Atributos involucrados
A12: ='M-Categoria'!E5 -> CategoriaUnica | B12: ='M-Categoria'!E4 -> Combinación única que indica que no puede existir más de una categoría con el mismo nombre y perteneciendo a la misma categoríaPadre | C12: Nombre
C13: CategoriaPadre
A17: Responsabilidad | C17: Descripción | G17: Entradas | J17: Salida | O17: Políticas (Reglas de Negocio) | Q17: Excepción
G18: Parámetro | H18: Tipo de dato | I18: Descripción | J18: Tipo de Dato | K18: Descripción | O18: Política | P18: Descripción | Q18: Detalle | R18: ¿Qué hago?
A19: registrarCategoria | C19: Permite registrar una nueva categoría en el sistema | G19: datos | H19: Categoria | I19: Contiene la información requerida para registrar la categoría | J19: Categoria | K19: Objeto de la categoría registrada con su identificador ID asignado, nombre, su categoría padre y nivel correspondientes | O19: =HYPERLINK("#'P-Categoria'!A5",'P-Categoria'!A5) -> P-CAT-001 | P19: ='P-Categoria'!B5 -> Asegurar que el id de categoría debe ser único e irrepetible | Q19: Generar un nuevo identificador hasta garantizar que no exista | R19: Continuar operación
O20: =HYPERLINK("#'P-Categoria'!A6",'P-Categoria'!A6) -> P-CAT-002 | P20: ='P-Categoria'!B6 -> Asegurar que el campo nombre de categoría debe ser único e irrepetible en su respectivo nivel de categoría padre | Q20: Generar una excepción indicando que ya existe una categoría con ese mismo nombre en ese mismo nivel | R20: Detener operación
O21: =HYPERLINK("#'P-Categoria'!A7",'P-Categoria'!A7) -> P-CAT-003 | P21: ='P-Categoria'!B7 -> Asegurar que los datos requeridos sean válidos en tipo de dato, longitud, obligatoriedad y formato | Q21: Generar una excepción indicando que los datos requeridos son inválidos o están incompletos | R21: Detener operación
A22: consultarCategoriasPorFiltro | C22: Permite buscar, listar y filtrar las categorías según los criterios de búsqueda enviados, ya sea id, nombre, categoriapadre o nivel | G22: filtro | H22: Categoria | I22: Contiene los parámetros o criterios de búsqueda enviados para filtrar la consulta | J22: Lista<Categoria> | K22: Contiene la lista de categorías que cumplen con las condiciones del filtro enviado | O22: =HYPERLINK("#'P-Categoria'!A7",'P-Categoria'!A7) -> P-CAT-003 | P22: ='P-Categoria'!B7 -> Asegurar que los datos requeridos sean válidos en tipo de dato, longitud, obligatoriedad y formato | Q22: Generar una excepción indicando que los datos requeridos son inválidos o están incompletos | R22: Detener operación
A23: modificarCategoria | C23: Permite actualizar la información de una categoría existente | G23: id | H23: UUID | I23: Tiene el identificador único de la categoría a modificar y la nueva información requerida para modificar la categoría existente | J23: Categoria | K23: Objeto de la categoría con su información actualizada | O23: =HYPERLINK("#'P-Categoria'!A6",'P-Categoria'!A6) -> P-CAT-002 | P23: ='P-Categoria'!B6 -> Asegurar que el campo nombre de categoría debe ser único e irrepetible en su respectivo nivel de categoría padre | Q23: Generar una excepción indicando que ya existe una categoría con ese mismo nombre en ese mismo nivel | R23: Detener operación
G24: datos | H24: Categoria | O24: =HYPERLINK("#'P-Categoria'!A7",'P-Categoria'!A7) -> P-CAT-003 | P24: ='P-Categoria'!B7 -> Asegurar que los datos requeridos sean válidos en tipo de dato, longitud, obligatoriedad y formato | Q24: Generar una excepción indicando que los datos requeridos son inválidos o están incompletos | R24: Detener operación
O25: ='P-Categoria'!A8 -> P-CAT-004 | P25: ='P-Categoria'!B8 -> Asegurar que no se asigne como categoría padre a la misma categoría o a cualquier subcategoría que dependa de ella | Q25: Generar una excepción indicando que no se puede asignar como categoría padre a sí misma ni a una de sus subcategorías | R25: Detener operación
A26: eliminarCategoria | C26: Permite eliminar una categoría si no posee ningun objeto de dominio dentro de ella | G26: id | H26: UUID | I26: Contiene el identificador único de la categoría que se desea eliminar | O26: =HYPERLINK("#'P-Categoria'!A7",'P-Categoria'!A7) -> P-CAT-003 | P26: ='P-Categoria'!B7 -> Asegurar que los datos requeridos sean válidos en tipo de dato, longitud, obligatoriedad y formato | Q26: Generar una excepción indicando que los datos requeridos son inválidos o están incompletos | R26: Detener operación
O27: ='P-Categoria'!A9 -> P-CAT-005 | P27: ='P-Categoria'!B9 -> Asegurar que la categoría no tenga ningún producto o categoría dependiendo de ella | Q27: Generar una excepción indicando al usuario que un producto o categoría está presente dentro de la misma | R27: Detener operación

Sheet E-Categoria
A1: <<<Ir al modelo de dominio | B1: <<<Ir a objeto de dominio | C1: <<<Ir a muestreo del objeto | D1: <<<Ir a caracterización | E1: Ir a las políticas>>>
A2: Objeto de Dominio: | B2: ='Objetos de Dominio'!A9 -> Categoria
A3: Descripción: | B3: ='Objetos de Dominio'!B9 -> Representa la clasificación a la que pertenece un producto dentro del catálogo.
A4: Actor | B4: Action/Command | D4: Entity/Aggregate/Object domain | E4: Read Model | G4: Business Rule/Policy | I4: External System | J4: Domain Event | K4: Hotspot/questions/Risk
